distribution.py[LINE:35]# ERROR    [2021-06-12 15:25:01,283]  Getting report error: 'v1_analytics_data_today' for report v1_analytics_data_today for client_id 33333333 
distribution.py[LINE:35]# ERROR    [2021-06-12 15:25:01,283]  Getting report error: 'v1_analytics_data_today' for report v1_analytics_data_today for client_id 33333333 
distribution.py[LINE:35]# ERROR    [2021-06-12 15:33:45,741]  Getting report error: 'v1_analytics_data_today' for report v1_analytics_data_today for client_id 33333333 
distribution.py[LINE:35]# ERROR    [2021-06-12 15:33:45,741]  Getting report error: 'v1_analytics_data_today' for report v1_analytics_data_today for client_id 33333333 
distribution.py[LINE:35]# ERROR    [2021-06-12 15:41:09,920]  Getting report error: 'v1_analytics_data_today' for report v1_analytics_data_today for client_id 80079 
distribution.py[LINE:35]# ERROR    [2021-06-12 15:41:09,920]  Getting report error: 'v1_analytics_data_today' for report v1_analytics_data_today for client_id 80079 
distribution.py[LINE:35]# ERROR    [2021-06-12 15:41:33,486]  Getting report error: 'v1_analytics_data_today' for report v1_analytics_data_today for client_id 80079 
distribution.py[LINE:35]# ERROR    [2021-06-12 15:41:33,486]  Getting report error: 'v1_analytics_data_today' for report v1_analytics_data_today for client_id 80079 
distribution.py[LINE:35]# ERROR    [2021-06-12 15:48:20,377]  Getting report error: 'v1_analytics_data_today' for report v1_analytics_data_today for client_id 80079 
distribution.py[LINE:35]# ERROR    [2021-06-12 15:48:20,377]  Getting report error: 'v1_analytics_data_today' for report v1_analytics_data_today for client_id 80079 
distribution.py[LINE:35]# ERROR    [2021-07-01 18:09:39,369]  Getting report error: 'v2_finance_transaction_month_from_month_ago_to_today' for report v2_finance_transaction_month_from_month_ago_to_today for client_id 150517 
distribution.py[LINE:35]# ERROR    [2021-07-01 18:09:39,369]  Getting report error: 'v2_finance_transaction_month_from_month_ago_to_today' for report v2_finance_transaction_month_from_month_ago_to_today for client_id 150517 
distribution.py[LINE:35]# ERROR    [2021-08-05 08:51:38,146]  Getting report error: 'v1_analytics_data_today' for report v1_analytics_data_today for client_id 80079 
distribution.py[LINE:35]# ERROR    [2021-08-05 08:51:38,146]  Getting report error: 'v1_analytics_data_today' for report v1_analytics_data_today for client_id 80079 
distribution.py[LINE:35]# ERROR    [2021-08-07 15:19:23,482]  Getting report error: 'v1_analytics_data_today' for report v1_analytics_data_today for client_id 80079 
distribution.py[LINE:35]# ERROR    [2021-08-07 15:19:23,482]  Getting report error: 'v1_analytics_data_today' for report v1_analytics_data_today for client_id 80079 
distribution.py[LINE:35]# ERROR    [2021-08-07 15:19:30,299]  Getting report error: 'v1_analytics_data_today' for report v1_analytics_data_today for client_id 80079 
distribution.py[LINE:35]# ERROR    [2021-08-07 15:19:30,299]  Getting report error: 'v1_analytics_data_today' for report v1_analytics_data_today for client_id 80079 
distribution.py[LINE:35]# ERROR    [2021-08-08 04:45:55,226]  Getting report error: 'v1_analytics_data_today' for report v1_analytics_data_today for client_id 80079 
distribution.py[LINE:35]# ERROR    [2021-08-08 04:45:55,226]  Getting report error: 'v1_analytics_data_today' for report v1_analytics_data_today for client_id 80079 
distribution.py[LINE:35]# ERROR    [2021-08-10 14:33:20,560]  Getting report error: 'v1_analytics_data_today' for report v1_analytics_data_today for client_id 80079 
distribution.py[LINE:35]# ERROR    [2021-08-10 14:33:20,560]  Getting report error: 'v1_analytics_data_today' for report v1_analytics_data_today for client_id 80079 
distribution.py[LINE:35]# ERROR    [2021-08-12 10:34:16,767]  Getting report error: 'v1_analytics_data_today' for report v1_analytics_data_today for client_id 80079 
distribution.py[LINE:35]# ERROR    [2021-08-12 10:34:16,767]  Getting report error: 'v1_analytics_data_today' for report v1_analytics_data_today for client_id 80079 
distribution.py[LINE:35]# ERROR    [2021-08-12 14:35:48,362]  Getting report error: 'v1_analytics_data_today' for report v1_analytics_data_today for client_id 80079 
distribution.py[LINE:35]# ERROR    [2021-08-12 14:35:48,362]  Getting report error: 'v1_analytics_data_today' for report v1_analytics_data_today for client_id 80079 
distribution.py[LINE:35]# ERROR    [2021-08-12 14:36:04,616]  Getting report error: 'v1_analytics_data_today' for report v1_analytics_data_today for client_id 80079 
distribution.py[LINE:35]# ERROR    [2021-08-12 14:36:04,616]  Getting report error: 'v1_analytics_data_today' for report v1_analytics_data_today for client_id 80079 
distribution.py[LINE:35]# ERROR    [2021-08-12 14:37:13,831]  Getting report error: 'v1_analytics_data_today' for report v1_analytics_data_today for client_id 80079 
distribution.py[LINE:35]# ERROR    [2021-08-12 14:37:13,831]  Getting report error: 'v1_analytics_data_today' for report v1_analytics_data_today for client_id 80079 
distribution.py[LINE:35]# ERROR    [2021-08-12 15:55:39,465]  Getting report error: 'v1_analytics_data_today' for report v1_analytics_data_today for client_id 80079 
distribution.py[LINE:35]# ERROR    [2021-08-12 15:55:39,465]  Getting report error: 'v1_analytics_data_today' for report v1_analytics_data_today for client_id 80079 
distribution.py[LINE:35]# ERROR    [2021-08-12 15:57:33,499]  Getting report error: 'v1_analytics_data_today' for report v1_analytics_data_today for client_id 80079 
distribution.py[LINE:35]# ERROR    [2021-08-12 15:57:33,499]  Getting report error: 'v1_analytics_data_today' for report v1_analytics_data_today for client_id 80079 
distribution.py[LINE:35]# ERROR    [2021-08-12 17:23:27,456]  Getting report error: 'v1_analytics_data_today' for report v1_analytics_data_today for client_id 80079 
distribution.py[LINE:35]# ERROR    [2021-08-12 17:23:27,456]  Getting report error: 'v1_analytics_data_today' for report v1_analytics_data_today for client_id 80079 
distribution.py[LINE:35]# ERROR    [2021-08-12 21:28:48,261]  Getting report error: 'v1_analytics_data_today' for report v1_analytics_data_today for client_id 80079 
distribution.py[LINE:35]# ERROR    [2021-08-12 21:28:48,261]  Getting report error: 'v1_analytics_data_today' for report v1_analytics_data_today for client_id 80079 
distribution.py[LINE:35]# ERROR    [2021-08-12 21:29:50,785]  Getting report error: 'v1_analytics_data_today' for report v1_analytics_data_today for client_id 80079 
distribution.py[LINE:35]# ERROR    [2021-08-12 21:29:50,785]  Getting report error: 'v1_analytics_data_today' for report v1_analytics_data_today for client_id 80079 
distribution.py[LINE:35]# ERROR    [2021-08-13 14:04:36,529]  Getting report error: 'v1_analytics_data_today' for report v1_analytics_data_today for client_id 80079 
distribution.py[LINE:35]# ERROR    [2021-08-13 14:04:36,529]  Getting report error: 'v1_analytics_data_today' for report v1_analytics_data_today for client_id 80079 
distribution.py[LINE:35]# ERROR    [2021-08-13 14:04:50,932]  Getting report error: 'v1_analytics_data_today' for report v1_analytics_data_today for client_id 836 
distribution.py[LINE:35]# ERROR    [2021-08-13 14:04:50,932]  Getting report error: 'v1_analytics_data_today' for report v1_analytics_data_today for client_id 836 
distribution.py[LINE:35]# ERROR    [2021-08-13 14:05:06,985]  Getting report error: 'v1_analytics_data_today' for report v1_analytics_data_today for client_id 836 
distribution.py[LINE:35]# ERROR    [2021-08-13 14:05:06,985]  Getting report error: 'v1_analytics_data_today' for report v1_analytics_data_today for client_id 836 
distribution.py[LINE:35]# ERROR    [2021-08-13 14:25:41,913]  Getting report error: 'v1_analytics_data_today' for report v1_analytics_data_today for client_id 836 
distribution.py[LINE:35]# ERROR    [2021-08-13 14:25:41,913]  Getting report error: 'v1_analytics_data_today' for report v1_analytics_data_today for client_id 836 
